Workbook

Sheet Table
A1: Asset | B1: Avg Daily Return | C1: Daily Volatility | D1: Annual Return | E1: Annual Volatility
A2: AAPL | B2: =AAPL!E2 -> 0.0012281601 | C2: =AAPL!F2 -> 0.019535514 | D2: =AAPL!G2 -> 0.30949634 | E2: =AAPL!H2 -> 0.31011666
A3: MSFT | B3: =MSFT!E2 -> 0.0010041431 | C3: =MSFT!F2 -> 0.017861536 | D3: =MSFT!G2 -> 0.25304406 | E3: =MSFT!H2 -> 0.28354309
A4: NVDA | B4: =NVDA!E2 -> 0.002780412 | C4: =NVDA!F2 -> 0.032414412 | D4: =NVDA!G2 -> 0.70066381 | E4: =NVDA!H2 -> 0.51456284
A5: JPM | B5: =JPM!E2 -> 0.00080893763 | C5: =JPM!F2 -> 0.018879395 | D5: =JPM!G2 -> 0.20385228 | E5: =JPM!H2 -> 0.2997011
A6: BAC | B6: =BAC!E2 -> 0.00063433089 | C6: =BAC!F2 -> 0.0207822 | D6: =BAC!G2 -> 0.15985138 | E6: =BAC!H2 -> 0.32990719
A7: KO | B7: =KO!E2 -> 0.00031991262 | C7: =KO!F2 -> 0.012544537 | D7: =KO!G2 -> 0.080617981 | E7: =KO!H2 -> 0.19913835
A8: SPY | B8: =SPY!E2 -> 0.00064941407 | C8: =SPY!F2 -> 0.012465144 | D8: =SPY!G2 -> 0.16365235 | E8: =SPY!H2 -> 0.19787803

Sheet Summary
A1: Asset | B1: Annual Return | C1: Annual Volatility | D1: Sharpe Ratio
A2: AAPL | B2: =AAPL!G2 -> 0.30949634 | C2: =AAPL!H2 -> 0.31011666 | D2: =(B2-0.03)/C2 -> 0.90126191
A3: MSFT | B3: =MSFT!G2 -> 0.25304406 | C3: =MSFT!H2 -> 0.28354309 | D3: =(B3-0.03)/C3 -> 0.78663197
A4: NVDA | B4: =NVDA!G2 -> 0.70066381 | C4: =NVDA!H2 -> 0.51456284 | D4: =(B4-0.03)/C4 -> 1.3033662
A5: JPM | B5: =JPM!G2 -> 0.20385228 | C5: =JPM!H2 -> 0.2997011 | D5: =(B5-0.03)/C5 -> 0.58008556
A6: BAC | B6: =BAC!G2 -> 0.15985138 | C6: =BAC!H2 -> 0.32990719 | D6: =(B6-0.03)/C6 -> 0.39359974
A7: KO | B7: =KO!G2 -> 0.080617981 | C7: =KO!H2 -> 0.19913835 | D7: =(B7-0.03)/C7 -> 0.25418499
A8: SPY | B8: =SPY!G2 -> 0.16365235 | C8: =SPY!H2 -> 0.19787803 | D8: =(B8-0.03)/C8 -> 0.67542793

Sheet AAPL
A1: =IFERROR(__xludf.UNSUPPORTED(GOOGLEFINANCE("AAPL", "price", "01/01/2019", "01/22/2026", "DAILY")),"Date") -> Date | B1: =IFERROR(__xludf.UNSUPPORTED("""COMPUTED_VALUE"""),"Close") -> Close | C1: daily_return | E1: avg_daily_return | F1: volatility | G1: annualized_return | H1: annualized_volatility
A2: =IFERROR(__xludf.UNSUPPORTED("""COMPUTED_VALUE"""),43467.6666666666) -> 43467.667 | B2: =IFERROR(__xludf.UNSUPPORTED("""COMPUTED_VALUE"""),39.48) -> 39.48 | E2: =AVERAGE(C3:C1775) -> 0.0012281601 | F2: =_xlfn.STDEV.S(C3:C1775) -> 0.019535514 | G2: =E2*252 -> 0.30949634 | H2: =F2*SQRT(252) -> 0.31011666
A3: =IFERROR(__xludf.UNSUPPORTED("""COMPUTED_VALUE"""),43468.6666666666) -> 43468.667 | B3: =IFERROR(__xludf.UNSUPPORTED("""COMPUTED_VALUE"""),35.55) -> 35.55 | C3: =(B3-B2)/B2 -> -0.099544073
A4: =IFERROR(__xludf.UNSUPPORTED("""COMPUTED_VALUE"""),43469.6666666666) -> 43469.667 | B4: =IFERROR(__xludf.UNSUPPORTED("""COMPUTED_VALUE"""),37.07) -> 37.07 | C4: =(B4-B3)/B3 -> 0.042756681
A5: =IFERROR(__xludf.UNSUPPORTED("""COMPUTED_VALUE"""),43472.6666666666) -> 43472.667 | B5: =IFERROR(__xludf.UNSUPPORTED("""COMPUTED_VALUE"""),36.98) -> 36.98 | C5: =(B5-B4)/B4 -> -0.0024278392
A6: =IFERROR(__xludf.UNSUPPORTED("""COMPUTED_VALUE"""),43473.6666666666) -> 43473.667 | B6: =IFERROR(__xludf.UNSUPPORTED("""COMPUTED_VALUE"""),37.69) -> 37.69 | C6: =(B6-B5)/B5 -> 0.019199567
A7: =IFERROR(__xludf.UNSUPPORTED("""COMPUTED_VALUE"""),43474.6666666666) -> 43474.667 | B7: =IFERROR(__xludf.UNSUPPORTED("""COMPUTED_VALUE"""),38.33) -> 38.33 | C7: =(B7-B6)/B6 -> 0.016980631
A8: =IFERROR(__xludf.UNSUPPORTED("""COMPUTED_VALUE"""),43475.6666666666) -> 43475.667 | B8: =IFERROR(__xludf.UNSUPPORTED("""COMPUTED_VALUE"""),38.45) -> 38.45 | C8: =(B8-B7)/B7 -> 0.003130707
A9: =IFERROR(__xludf.UNSUPPORTED("""COMPUTED_VALUE"""),43476.6666666666) -> 43476.667 | B9: =IFERROR(__xludf.UNSUPPORTED("""COMPUTED_VALUE"""),38.07) -> 38.07 | C9: =(B9-B8)/B8 -> -0.0098829649
A10: =IFERROR(__xludf.UNSUPPORTED("""COMPUTED_VALUE"""),43479.6666666666) -> 43479.667 | B10: =IFERROR(__xludf.UNSUPPORTED("""COMPUTED_VALUE"""),37.5) -> 37.5 | C10: =(B10-B9)/B9 -> -0.014972419
A11: =IFERROR(__xludf.UNSUPPORTED("""COMPUTED_VALUE"""),43480.6666666666) -> 43480.667 | B11: =IFERROR(__xludf.UNSUPPORTED("""COMPUTED_VALUE"""),38.27) -> 38.27 | C11: =(B11-B10)/B10 -> 0.020533333
A12: =IFERROR(__xludf.UNSUPPORTED("""COMPUTED_VALUE"""),43481.6666666666) -> 43481.667 | B12: =IFERROR(__xludf.UNSUPPORTED("""COMPUTED_VALUE"""),38.74) -> 38.74 | C12: =(B12-B11)/B11 -> 0.01228116
A13: =IFERROR(__xludf.UNSUPPORTED("""COMPUTED_VALUE"""),43482.6666666666) -> 43482.667 | B13: =IFERROR(__xludf.UNSUPPORTED("""COMPUTED_VALUE"""),38.97) -> 38.97 | C13: =(B13-B12)/B12 -> 0.005937016
A14: =IFERROR(__xludf.UNSUPPORTED("""COMPUTED_VALUE"""),43483.6666666666) -> 43483.667 | B14: =IFERROR(__xludf.UNSUPPORTED("""COMPUTED_VALUE"""),39.21) -> 39.21 | C14: =(B14-B13)/B13 -> 0.0061585835
A15: =IFERROR(__xludf.UNSUPPORTED("""COMPUTED_VALUE"""),43487.6666666666) -> 43487.667 | B15: =IFERROR(__xludf.UNSUPPORTED("""COMPUTED_VALUE"""),38.33) -> 38.33 | C15: =(B15-B14)/B14 -> -0.022443254
A16: =IFERROR(__xludf.UNSUPPORTED("""COMPUTED_VALUE"""),43488.6666666666) -> 43488.667 | B16: =IFERROR(__xludf.UNSUPPORTED("""COMPUTED_VALUE"""),38.48) -> 38.48 | C16: =(B16-B15)/B15 -> 0.0039133838
A17: =IFERROR(__xludf.UNSUPPORTED("""COMPUTED_VALUE"""),43489.6666666666) -> 43489.667 | B17: =IFERROR(__xludf.UNSUPPORTED("""COMPUTED_VALUE"""),38.17) -> 38.17 | C17: =(B17-B16)/B16 -> -0.0080561331
A18: =IFERROR(__xludf.UNSUPPORTED("""COMPUTED_VALUE"""),43490.6666666666) -> 43490.667 | B18: =IFERROR(__xludf.UNSUPPORTED("""COMPUTED_VALUE"""),39.44) -> 39.44 | C18: =(B18-B17)/B17 -> 0.033272203
A19: =IFERROR(__xludf.UNSUPPORTED("""COMPUTED_VALUE"""),43493.6666666666) -> 43493.667 | B19: =IFERROR(__xludf.UNSUPPORTED("""COMPUTED_VALUE"""),39.08) -> 39.08 | C19: =(B19-B18)/B18 -> -0.009127789
A20: =IFERROR(__xludf.UNSUPPORTED("""COMPUTED_VALUE"""),43494.6666666666) -> 43494.667 | B20: =IFERROR(__xludf.UNSUPPORTED("""COMPUTED_VALUE"""),38.67) -> 38.67 | C20: =(B20-B19)/B19 -> -0.0104913
A21: =IFERROR(__xludf.UNSUPPORTED("""COMPUTED_VALUE"""),43495.6666666666) -> 43495.667 | B21: =IFERROR(__xludf.UNSUPPORTED("""COMPUTED_VALUE"""),41.31) -> 41.31 | C21: =(B21-B20)/B20 -> 0.068269977
A22: =IFERROR(__xludf.UNSUPPORTED("""COMPUTED_VALUE"""),43496.6666666666) -> 43496.667 | B22: =IFERROR(__xludf.UNSUPPORTED("""COMPUTED_VALUE"""),41.61) -> 41.61 | C22: =(B22-B21)/B21 -> 0.0072621641
A23: =IFERROR(__xludf.UNSUPPORTED("""COMPUTED_VALUE"""),43497.6666666666) -> 43497.667 | B23: =IFERROR(__xludf.UNSUPPORTED("""COMPUTED_VALUE"""),41.63) -> 41.63 | C23: =(B23-B22)/B22 -> 0.00048065369
A24: =IFERROR(__xludf.UNSUPPORTED("""COMPUTED_VALUE"""),43500.6666666666) -> 43500.667 | B24: =IFERROR(__xludf.UNSUPPORTED("""COMPUTED_VALUE"""),42.81) -> 42.81 | C24: =(B24-B23)/B23 -> 0.028344944
A25: =IFERROR(__xludf.UNSUPPORTED("""COMPUTED_VALUE"""),43501.6666666666) -> 43501.667 | B25: =IFERROR(__xludf.UNSUPPORTED("""COMPUTED_VALUE"""),43.55) -> 43.55 | C25: =(B25-B24)/B24 -> 0.017285681
A26: =IFERROR(__xludf.UNSUPPORTED("""COMPUTED_VALUE"""),43502.6666666666) -> 43502.667 | B26: =IFERROR(__xludf.UNSUPPORTED("""COMPUTED_VALUE"""),43.56) -> 43.56 | C26: =(B26-B25)/B25 -> 0.00022962113
A27: =IFERROR(__xludf.UNSUPPORTED("""COMPUTED_VALUE"""),43503.6666666666) -> 43503.667 | B27: =IFERROR(__xludf.UNSUPPORTED("""COMPUTED_VALUE"""),42.74) -> 42.74 | C27: =(B27-B26)/B26 -> -0.01882461
A28: =IFERROR(__xludf.UNSUPPORTED("""COMPUTED_VALUE"""),43504.6666666666) -> 43504.667 | B28: =IFERROR(__xludf.UNSUPPORTED("""COMPUTED_VALUE"""),42.6) -> 42.6 | C28: =(B28-B27)/B27 -> -0.00327562
A29: =IFERROR(__xludf.UNSUPPORTED("""COMPUTED_VALUE"""),43507.6666666666) -> 43507.667 | B29: =IFERROR(__xludf.UNSUPPORTED("""COMPUTED_VALUE"""),42.36) -> 42.36 | C29: =(B29-B28)/B28 -> -0.0056338028
A30: =IFERROR(__xludf.UNSUPPORTED("""COMPUTED_VALUE"""),43508.6666666666) -> 43508.667 | B30: =IFERROR(__xludf.UNSUPPORTED("""COMPUTED_VALUE"""),42.72) -> 42.72 | C30: =(B30-B29)/B29 -> 0.0084985836
A31: =IFERROR(__xludf.UNSUPPORTED("""COMPUTED_VALUE"""),43509.6666666666) -> 43509.667 | B31: =IFERROR(__xludf.UNSUPPORTED("""COMPUTED_VALUE"""),42.55) -> 42.55 | C31: =(B31-B30)/B30 -> -0.0039794007
A32: =IFERROR(__xludf.UNSUPPORTED("""COMPUTED_VALUE"""),43510.6666666666) -> 43510.667 | B32: =IFERROR(__xludf.UNSUPPORTED("""COMPUTED_VALUE"""),42.7) -> 42.7 | C32: =(B32-B31)/B31 -> 0.0035252644
A33: =IFERROR(__xludf.UNSUPPORTED("""COMPUTED_VALUE"""),43511.6666666666) -> 43511.667 | B33: =IFERROR(__xludf.UNSUPPORTED("""COMPUTED_VALUE"""),42.61) -> 42.61 | C33: =(B33-B32)/B32 -> -0.0021077283
A34: =IFERROR(__xludf.UNSUPPORTED("""COMPUTED_VALUE"""),43515.6666666666) -> 43515.667 | B34: =IFERROR(__xludf.UNSUPPORTED("""COMPUTED_VALUE"""),42.73) -> 42.73 | C34: =(B34-B33)/B33 -> 0.0028162403
A35: =IFERROR(__xludf.UNSUPPORTED("""COMPUTED_VALUE"""),43516.6666666666) -> 43516.667 | B35: =IFERROR(__xludf.UNSUPPORTED("""COMPUTED_VALUE"""),43.01) -> 43.01 | C35: =(B35-B34)/B34 -> 0.0065527732
A36: =IFERROR(__xludf.UNSUPPORTED("""COMPUTED_VALUE"""),43517.6666666666) -> 43517.667 | B36: =IFERROR(__xludf.UNSUPPORTED("""COMPUTED_VALUE"""),42.77) -> 42.77 | C36: =(B36-B35)/B35 -> -0.0055800977
A37: =IFERROR(__xludf.UNSUPPORTED("""COMPUTED_VALUE"""),43518.6666666666) -> 43518.667 | B37: =IFERROR(__xludf.UNSUPPORTED("""COMPUTED_VALUE"""),43.24) -> 43.24 | C37: =(B37-B36)/B36 -> 0.010989011
A38: =IFERROR(__xludf.UNSUPPORTED("""COMPUTED_VALUE"""),43521.6666666666) -> 43521.667 | B38: =IFERROR(__xludf.UNSUPPORTED("""COMPUTED_VALUE"""),43.56) -> 43.56 | C38: =(B38-B37)/B37 -> 0.007400555
A39: =IFERROR(__xludf.UNSUPPORTED("""COMPUTED_VALUE"""),43522.6666666666) -> 43522.667 | B39: =IFERROR(__xludf.UNSUPPORTED("""COMPUTED_VALUE"""),43.58) -> 43.58 | C39: =(B39-B38)/B38 -> 0.00045913682
A40: =IFERROR(__xludf.UNSUPPORTED("""COMPUTED_VALUE"""),43523.6666666666) -> 43523.667 | B40: =IFERROR(__xludf.UNSUPPORTED("""COMPUTED_VALUE"""),43.72) -> 43.72 | C40: =(B40-B39)/B39 -> 0.0032124828
...

Sheet MSFT
A1: =IFERROR(__xludf.UNSUPPORTED(GOOGLEFINANCE("MSFT", "price", "01/01/2019", "01/22/2026", "DAILY")),"Date") -> Date | B1: =IFERROR(__xludf.UNSUPPORTED("""COMPUTED_VALUE"""),"Close") -> Close | C1: daily_return | E1: avg_daily_return | F1: volatility | G1: annualized_return | H1: annualized_volatility
A2: =IFERROR(__xludf.UNSUPPORTED("""COMPUTED_VALUE"""),43467.6666666666) -> 43467.667 | B2: =IFERROR(__xludf.UNSUPPORTED("""COMPUTED_VALUE"""),101.12) -> 101.12 | E2: =AVERAGE(C3:C1773) -> 0.0010041431 | F2: =_xlfn.STDEV.S(C3:C1773) -> 0.017861536 | G2: =E2*252 -> 0.25304406 | H2: =F2*SQRT(252) -> 0.28354309
A3: =IFERROR(__xludf.UNSUPPORTED("""COMPUTED_VALUE"""),43468.6666666666) -> 43468.667 | B3: =IFERROR(__xludf.UNSUPPORTED("""COMPUTED_VALUE"""),97.4) -> 97.4 | C3: =(B3-B2)/B2 -> -0.036787975
A4: =IFERROR(__xludf.UNSUPPORTED("""COMPUTED_VALUE"""),43469.6666666666) -> 43469.667 | B4: =IFERROR(__xludf.UNSUPPORTED("""COMPUTED_VALUE"""),101.93) -> 101.93 | C4: =(B4-B3)/B3 -> 0.04650924
A5: =IFERROR(__xludf.UNSUPPORTED("""COMPUTED_VALUE"""),43472.6666666666) -> 43472.667 | B5: =IFERROR(__xludf.UNSUPPORTED("""COMPUTED_VALUE"""),102.06) -> 102.06 | C5: =(B5-B4)/B4 -> 0.0012753851
A6: =IFERROR(__xludf.UNSUPPORTED("""COMPUTED_VALUE"""),43473.6666666666) -> 43473.667 | B6: =IFERROR(__xludf.UNSUPPORTED("""COMPUTED_VALUE"""),102.8) -> 102.8 | C6: =(B6-B5)/B5 -> 0.0072506369
A7: =IFERROR(__xludf.UNSUPPORTED("""COMPUTED_VALUE"""),43474.6666666666) -> 43474.667 | B7: =IFERROR(__xludf.UNSUPPORTED("""COMPUTED_VALUE"""),104.27) -> 104.27 | C7: =(B7-B6)/B6 -> 0.014299611
A8: =IFERROR(__xludf.UNSUPPORTED("""COMPUTED_VALUE"""),43475.6666666666) -> 43475.667 | B8: =IFERROR(__xludf.UNSUPPORTED("""COMPUTED_VALUE"""),103.6) -> 103.6 | C8: =(B8-B7)/B7 -> -0.0064256258
A9: =IFERROR(__xludf.UNSUPPORTED("""COMPUTED_VALUE"""),43476.6666666666) -> 43476.667 | B9: =IFERROR(__xludf.UNSUPPORTED("""COMPUTED_VALUE"""),102.8) -> 102.8 | C9: =(B9-B8)/B8 -> -0.0077220077
A10: =IFERROR(__xludf.UNSUPPORTED("""COMPUTED_VALUE"""),43479.6666666666) -> 43479.667 | B10: =IFERROR(__xludf.UNSUPPORTED("""COMPUTED_VALUE"""),102.05) -> 102.05 | C10: =(B10-B9)/B9 -> -0.0072957198
A11: =IFERROR(__xludf.UNSUPPORTED("""COMPUTED_VALUE"""),43480.6666666666) -> 43480.667 | B11: =IFERROR(__xludf.UNSUPPORTED("""COMPUTED_VALUE"""),105.01) -> 105.01 | C11: =(B11-B10)/B10 -> 0.02900539
A12: =IFERROR(__xludf.UNSUPPORTED("""COMPUTED_VALUE"""),43481.6666666666) -> 43481.667 | B12: =IFERROR(__xludf.UNSUPPORTED("""COMPUTED_VALUE"""),105.38) -> 105.38 | C12: =(B12-B11)/B11 -> 0.003523474
A13: =IFERROR(__xludf.UNSUPPORTED("""COMPUTED_VALUE"""),43482.6666666666) -> 43482.667 | B13: =IFERROR(__xludf.UNSUPPORTED("""COMPUTED_VALUE"""),106.12) -> 106.12 | C13: =(B13-B12)/B12 -> 0.0070222054
A14: =IFERROR(__xludf.UNSUPPORTED("""COMPUTED_VALUE"""),43483.6666666666) -> 43483.667 | B14: =IFERROR(__xludf.UNSUPPORTED("""COMPUTED_VALUE"""),107.71) -> 107.71 | C14: =(B14-B13)/B13 -> 0.014983038
A15: =IFERROR(__xludf.UNSUPPORTED("""COMPUTED_VALUE"""),43487.6666666666) -> 43487.667 | B15: =IFERROR(__xludf.UNSUPPORTED("""COMPUTED_VALUE"""),105.68) -> 105.68 | C15: =(B15-B14)/B14 -> -0.018846904
A16: =IFERROR(__xludf.UNSUPPORTED("""COMPUTED_VALUE"""),43488.6666666666) -> 43488.667 | B16: =IFERROR(__xludf.UNSUPPORTED("""COMPUTED_VALUE"""),106.71) -> 106.71 | C16: =(B16-B15)/B15 -> 0.0097464042
A17: =IFERROR(__xludf.UNSUPPORTED("""COMPUTED_VALUE"""),43489.6666666666) -> 43489.667 | B17: =IFERROR(__xludf.UNSUPPORTED("""COMPUTED_VALUE"""),106.2) -> 106.2 | C17: =(B17-B16)/B16 -> -0.0047793084
A18: =IFERROR(__xludf.UNSUPPORTED("""COMPUTED_VALUE"""),43490.6666666666) -> 43490.667 | B18: =IFERROR(__xludf.UNSUPPORTED("""COMPUTED_VALUE"""),107.17) -> 107.17 | C18: =(B18-B17)/B17 -> 0.00913371
A19: =IFERROR(__xludf.UNSUPPORTED("""COMPUTED_VALUE"""),43493.6666666666) -> 43493.667 | B19: =IFERROR(__xludf.UNSUPPORTED("""COMPUTED_VALUE"""),105.08) -> 105.08 | C19: =(B19-B18)/B18 -> -0.019501726
A20: =IFERROR(__xludf.UNSUPPORTED("""COMPUTED_VALUE"""),43494.6666666666) -> 43494.667 | B20: =IFERROR(__xludf.UNSUPPORTED("""COMPUTED_VALUE"""),102.94) -> 102.94 | C20: =(B20-B19)/B19 -> -0.020365436
A21: =IFERROR(__xludf.UNSUPPORTED("""COMPUTED_VALUE"""),43495.6666666666) -> 43495.667 | B21: =IFERROR(__xludf.UNSUPPORTED("""COMPUTED_VALUE"""),106.38) -> 106.38 | C21: =(B21-B20)/B20 -> 0.033417525
A22: =IFERROR(__xludf.UNSUPPORTED("""COMPUTED_VALUE"""),43496.6666666666) -> 43496.667 | B22: =IFERROR(__xludf.UNSUPPORTED("""COMPUTED_VALUE"""),104.43) -> 104.43 | C22: =(B22-B21)/B21 -> -0.018330513
A23: =IFERROR(__xludf.UNSUPPORTED("""COMPUTED_VALUE"""),43497.6666666666) -> 43497.667 | B23: =IFERROR(__xludf.UNSUPPORTED("""COMPUTED_VALUE"""),102.78) -> 102.78 | C23: =(B23-B22)/B22 -> -0.015800057
A24: =IFERROR(__xludf.UNSUPPORTED("""COMPUTED_VALUE"""),43500.6666666666) -> 43500.667 | B24: =IFERROR(__xludf.UNSUPPORTED("""COMPUTED_VALUE"""),105.74) -> 105.74 | C24: =(B24-B23)/B23 -> 0.028799377
A25: =IFERROR(__xludf.UNSUPPORTED("""COMPUTED_VALUE"""),43501.6666666666) -> 43501.667 | B25: =IFERROR(__xludf.UNSUPPORTED("""COMPUTED_VALUE"""),107.22) -> 107.22 | C25: =(B25-B24)/B24 -> 0.013996595
A26: =IFERROR(__xludf.UNSUPPORTED("""COMPUTED_VALUE"""),43502.6666666666) -> 43502.667 | B26: =IFERROR(__xludf.UNSUPPORTED("""COMPUTED_VALUE"""),106.03) -> 106.03 | C26: =(B26-B25)/B25 -> -0.011098676
A27: =IFERROR(__xludf.UNSUPPORTED("""COMPUTED_VALUE"""),43503.6666666666) -> 43503.667 | B27: =IFERROR(__xludf.UNSUPPORTED("""COMPUTED_VALUE"""),105.27) -> 105.27 | C27: =(B27-B26)/B26 -> -0.0071677827
A28: =IFERROR(__xludf.UNSUPPORTED("""COMPUTED_VALUE"""),43504.6666666666) -> 43504.667 | B28: =IFERROR(__xludf.UNSUPPORTED("""COMPUTED_VALUE"""),105.67) -> 105.67 | C28: =(B28-B27)/B27 -> 0.003799753
A29: =IFERROR(__xludf.UNSUPPORTED("""COMPUTED_VALUE"""),43507.6666666666) -> 43507.667 | B29: =IFERROR(__xludf.UNSUPPORTED("""COMPUTED_VALUE"""),105.25) -> 105.25 | C29: =(B29-B28)/B28 -> -0.003974638
A30: =IFERROR(__xludf.UNSUPPORTED("""COMPUTED_VALUE"""),43508.6666666666) -> 43508.667 | B30: =IFERROR(__xludf.UNSUPPORTED("""COMPUTED_VALUE"""),106.89) -> 106.89 | C30: =(B30-B29)/B29 -> 0.015581948
A31: =IFERROR(__xludf.UNSUPPORTED("""COMPUTED_VALUE"""),43509.6666666666) -> 43509.667 | B31: =IFERROR(__xludf.UNSUPPORTED("""COMPUTED_VALUE"""),106.81) -> 106.81 | C31: =(B31-B30)/B30 -> -0.00074843297
A32: =IFERROR(__xludf.UNSUPPORTED("""COMPUTED_VALUE"""),43510.6666666666) -> 43510.667 | B32: =IFERROR(__xludf.UNSUPPORTED("""COMPUTED_VALUE"""),106.9) -> 106.9 | C32: =(B32-B31)/B31 -> 0.00084261773
A33: =IFERROR(__xludf.UNSUPPORTED("""COMPUTED_VALUE"""),43511.6666666666) -> 43511.667 | B33: =IFERROR(__xludf.UNSUPPORTED("""COMPUTED_VALUE"""),108.22) -> 108.22 | C33: =(B33-B32)/B32 -> 0.012347989
A34: =IFERROR(__xludf.UNSUPPORTED("""COMPUTED_VALUE"""),43515.6666666666) -> 43515.667 | B34: =IFERROR(__xludf.UNSUPPORTED("""COMPUTED_VALUE"""),108.17) -> 108.17 | C34: =(B34-B33)/B33 -> -0.00046202181
A35: =IFERROR(__xludf.UNSUPPORTED("""COMPUTED_VALUE"""),43516.6666666666) -> 43516.667 | B35: =IFERROR(__xludf.UNSUPPORTED("""COMPUTED_VALUE"""),107.15) -> 107.15 | C35: =(B35-B34)/B34 -> -0.0094296016
A36: =IFERROR(__xludf.UNSUPPORTED("""COMPUTED_VALUE"""),43517.6666666666) -> 43517.667 | B36: =IFERROR(__xludf.UNSUPPORTED("""COMPUTED_VALUE"""),109.41) -> 109.41 | C36: =(B36-B35)/B35 -> 0.021091927
A37: =IFERROR(__xludf.UNSUPPORTED("""COMPUTED_VALUE"""),43518.6666666666) -> 43518.667 | B37: =IFERROR(__xludf.UNSUPPORTED("""COMPUTED_VALUE"""),110.97) -> 110.97 | C37: =(B37-B36)/B36 -> 0.014258294
A38: =IFERROR(__xludf.UNSUPPORTED("""COMPUTED_VALUE"""),43521.6666666666) -> 43521.667 | B38: =IFERROR(__xludf.UNSUPPORTED("""COMPUTED_VALUE"""),111.59) -> 111.59 | C38: =(B38-B37)/B37 -> 0.0055870956
A39: =IFERROR(__xludf.UNSUPPORTED("""COMPUTED_VALUE"""),43522.6666666666) -> 43522.667 | B39: =IFERROR(__xludf.UNSUPPORTED("""COMPUTED_VALUE"""),112.36) -> 112.36 | C39: =(B39-B38)/B38 -> 0.0069002599
A40: =IFERROR(__xludf.UNSUPPORTED("""COMPUTED_VALUE"""),43523.6666666666) -> 43523.667 | B40: =IFERROR(__xludf.UNSUPPORTED("""COMPUTED_VALUE"""),112.17) -> 112.17 | C40: =(B40-B39)/B39 -> -0.0016909932
...

Sheet NVDA
A1: =IFERROR(__xludf.UNSUPPORTED(GOOGLEFINANCE("NVDA", "price", "01/01/2019", "01/22/2026", "DAILY")),"Date") -> Date | B1: =IFERROR(__xludf.UNSUPPORTED("""COMPUTED_VALUE"""),"Close") -> Close | C1: daily_return | E1: avg_daily_return | F1: volatility | G1: annualized_return | H1: annualized_volatility
A2: =IFERROR(__xludf.UNSUPPORTED("""COMPUTED_VALUE"""),43467.6666666666) -> 43467.667 | B2: =IFERROR(__xludf.UNSUPPORTED("""COMPUTED_VALUE"""),3.41) -> 3.41 | E2: =AVERAGE(C3:C1772) -> 0.002780412 | F2: =_xlfn.STDEV.S(C3:C1772) -> 0.032414412 | G2: =E2*252 -> 0.70066381 | H2: =F2*SQRT(252) -> 0.51456284
A3: =IFERROR(__xludf.UNSUPPORTED("""COMPUTED_VALUE"""),43468.6666666666) -> 43468.667 | B3: =IFERROR(__xludf.UNSUPPORTED("""COMPUTED_VALUE"""),3.2) -> 3.2 | C3: =(B3-B2)/B2 -> -0.061583578
A4: =IFERROR(__xludf.UNSUPPORTED("""COMPUTED_VALUE"""),43469.6666666666) -> 43469.667 | B4: =IFERROR(__xludf.UNSUPPORTED("""COMPUTED_VALUE"""),3.4) -> 3.4 | C4: =(B4-B3)/B3 -> 0.0625
A5: =IFERROR(__xludf.UNSUPPORTED("""COMPUTED_VALUE"""),43472.6666666666) -> 43472.667 | B5: =IFERROR(__xludf.UNSUPPORTED("""COMPUTED_VALUE"""),3.59) -> 3.59 | C5: =(B5-B4)/B4 -> 0.055882353
A6: =IFERROR(__xludf.UNSUPPORTED("""COMPUTED_VALUE"""),43473.6666666666) -> 43473.667 | B6: =IFERROR(__xludf.UNSUPPORTED("""COMPUTED_VALUE"""),3.5) -> 3.5 | C6: =(B6-B5)/B5 -> -0.025069638
A7: =IFERROR(__xludf.UNSUPPORTED("""COMPUTED_VALUE"""),43474.6666666666) -> 43474.667 | B7: =IFERROR(__xludf.UNSUPPORTED("""COMPUTED_VALUE"""),3.56) -> 3.56 | C7: =(B7-B6)/B6 -> 0.017142857
A8: =IFERROR(__xludf.UNSUPPORTED("""COMPUTED_VALUE"""),43475.6666666666) -> 43475.667 | B8: =IFERROR(__xludf.UNSUPPORTED("""COMPUTED_VALUE"""),3.63) -> 3.63 | C8: =(B8-B7)/B7 -> 0.019662921
A9: =IFERROR(__xludf.UNSUPPORTED("""COMPUTED_VALUE"""),43476.6666666666) -> 43476.667 | B9: =IFERROR(__xludf.UNSUPPORTED("""COMPUTED_VALUE"""),3.72) -> 3.72 | C9: =(B9-B8)/B8 -> 0.024793388
A10: =IFERROR(__xludf.UNSUPPORTED("""COMPUTED_VALUE"""),43479.6666666666) -> 43479.667 | B10: =IFERROR(__xludf.UNSUPPORTED("""COMPUTED_VALUE"""),3.76) -> 3.76 | C10: =(B10-B9)/B9 -> 0.010752688
A11: =IFERROR(__xludf.UNSUPPORTED("""COMPUTED_VALUE"""),43480.6666666666) -> 43480.667 | B11: =IFERROR(__xludf.UNSUPPORTED("""COMPUTED_VALUE"""),3.75) -> 3.75 | C11: =(B11-B10)/B10 -> -0.0026595745
A12: =IFERROR(__xludf.UNSUPPORTED("""COMPUTED_VALUE"""),43481.6666666666) -> 43481.667 | B12: =IFERROR(__xludf.UNSUPPORTED("""COMPUTED_VALUE"""),3.72) -> 3.72 | C12: =(B12-B11)/B11 -> -0.008
A13: =IFERROR(__xludf.UNSUPPORTED("""COMPUTED_VALUE"""),43482.6666666666) -> 43482.667 | B13: =IFERROR(__xludf.UNSUPPORTED("""COMPUTED_VALUE"""),3.79) -> 3.79 | C13: =(B13-B12)/B12 -> 0.018817204
A14: =IFERROR(__xludf.UNSUPPORTED("""COMPUTED_VALUE"""),43483.6666666666) -> 43483.667 | B14: =IFERROR(__xludf.UNSUPPORTED("""COMPUTED_VALUE"""),3.92) -> 3.92 | C14: =(B14-B13)/B13 -> 0.034300792
A15: =IFERROR(__xludf.UNSUPPORTED("""COMPUTED_VALUE"""),43487.6666666666) -> 43487.667 | B15: =IFERROR(__xludf.UNSUPPORTED("""COMPUTED_VALUE"""),3.72) -> 3.72 | C15: =(B15-B14)/B14 -> -0.051020408
A16: =IFERROR(__xludf.UNSUPPORTED("""COMPUTED_VALUE"""),43488.6666666666) -> 43488.667 | B16: =IFERROR(__xludf.UNSUPPORTED("""COMPUTED_VALUE"""),3.73) -> 3.73 | C16: =(B16-B15)/B15 -> 0.002688172
A17: =IFERROR(__xludf.UNSUPPORTED("""COMPUTED_VALUE"""),43489.6666666666) -> 43489.667 | B17: =IFERROR(__xludf.UNSUPPORTED("""COMPUTED_VALUE"""),3.95) -> 3.95 | C17: =(B17-B16)/B16 -> 0.058981233
A18: =IFERROR(__xludf.UNSUPPORTED("""COMPUTED_VALUE"""),43490.6666666666) -> 43490.667 | B18: =IFERROR(__xludf.UNSUPPORTED("""COMPUTED_VALUE"""),4) -> 4 | C18: =(B18-B17)/B17 -> 0.012658228
A19: =IFERROR(__xludf.UNSUPPORTED("""COMPUTED_VALUE"""),43493.6666666666) -> 43493.667 | B19: =IFERROR(__xludf.UNSUPPORTED("""COMPUTED_VALUE"""),3.45) -> 3.45 | C19: =(B19-B18)/B18 -> -0.1375
A20: =IFERROR(__xludf.UNSUPPORTED("""COMPUTED_VALUE"""),43494.6666666666) -> 43494.667 | B20: =IFERROR(__xludf.UNSUPPORTED("""COMPUTED_VALUE"""),3.29) -> 3.29 | C20: =(B20-B19)/B19 -> -0.046376812
A21: =IFERROR(__xludf.UNSUPPORTED("""COMPUTED_VALUE"""),43495.6666666666) -> 43495.667 | B21: =IFERROR(__xludf.UNSUPPORTED("""COMPUTED_VALUE"""),3.43) -> 3.43 | C21: =(B21-B20)/B20 -> 0.042553191
A22: =IFERROR(__xludf.UNSUPPORTED("""COMPUTED_VALUE"""),43496.6666666666) -> 43496.667 | B22: =IFERROR(__xludf.UNSUPPORTED("""COMPUTED_VALUE"""),3.59) -> 3.59 | C22: =(B22-B21)/B21 -> 0.04664723
A23: =IFERROR(__xludf.UNSUPPORTED("""COMPUTED_VALUE"""),43497.6666666666) -> 43497.667 | B23: =IFERROR(__xludf.UNSUPPORTED("""COMPUTED_VALUE"""),3.62) -> 3.62 | C23: =(B23-B22)/B22 -> 0.008356546
A24: =IFERROR(__xludf.UNSUPPORTED("""COMPUTED_VALUE"""),43500.6666666666) -> 43500.667 | B24: =IFERROR(__xludf.UNSUPPORTED("""COMPUTED_VALUE"""),3.73) -> 3.73 | C24: =(B24-B23)/B23 -> 0.03038674
A25: =IFERROR(__xludf.UNSUPPORTED("""COMPUTED_VALUE"""),43501.6666666666) -> 43501.667 | B25: =IFERROR(__xludf.UNSUPPORTED("""COMPUTED_VALUE"""),3.75) -> 3.75 | C25: =(B25-B24)/B24 -> 0.0053619303
A26: =IFERROR(__xludf.UNSUPPORTED("""COMPUTED_VALUE"""),43502.6666666666) -> 43502.667 | B26: =IFERROR(__xludf.UNSUPPORTED("""COMPUTED_VALUE"""),3.83) -> 3.83 | C26: =(B26-B25)/B25 -> 0.021333333
A27: =IFERROR(__xludf.UNSUPPORTED("""COMPUTED_VALUE"""),43503.6666666666) -> 43503.667 | B27: =IFERROR(__xludf.UNSUPPORTED("""COMPUTED_VALUE"""),3.69) -> 3.69 | C27: =(B27-B26)/B26 -> -0.036553525
A28: =IFERROR(__xludf.UNSUPPORTED("""COMPUTED_VALUE"""),43504.6666666666) -> 43504.667 | B28: =IFERROR(__xludf.UNSUPPORTED("""COMPUTED_VALUE"""),3.7) -> 3.7 | C28: =(B28-B27)/B27 -> 0.0027100271
A29: =IFERROR(__xludf.UNSUPPORTED("""COMPUTED_VALUE"""),43507.6666666666) -> 43507.667 | B29: =IFERROR(__xludf.UNSUPPORTED("""COMPUTED_VALUE"""),3.66) -> 3.66 | C29: =(B29-B28)/B28 -> -0.010810811
A30: =IFERROR(__xludf.UNSUPPORTED("""COMPUTED_VALUE"""),43508.6666666666) -> 43508.667 | B30: =IFERROR(__xludf.UNSUPPORTED("""COMPUTED_VALUE"""),3.78) -> 3.78 | C30: =(B30-B29)/B29 -> 0.032786885
A31: =IFERROR(__xludf.UNSUPPORTED("""COMPUTED_VALUE"""),43509.6666666666) -> 43509.667 | B31: =IFERROR(__xludf.UNSUPPORTED("""COMPUTED_VALUE"""),3.82) -> 3.82 | C31: =(B31-B30)/B30 -> 0.010582011
A32: =IFERROR(__xludf.UNSUPPORTED("""COMPUTED_VALUE"""),43510.6666666666) -> 43510.667 | B32: =IFERROR(__xludf.UNSUPPORTED("""COMPUTED_VALUE"""),3.86) -> 3.86 | C32: =(B32-B31)/B31 -> 0.010471204
A33: =IFERROR(__xludf.UNSUPPORTED("""COMPUTED_VALUE"""),43511.6666666666) -> 43511.667 | B33: =IFERROR(__xludf.UNSUPPORTED("""COMPUTED_VALUE"""),3.93) -> 3.93 | C33: =(B33-B32)/B32 -> 0.018134715
A34: =IFERROR(__xludf.UNSUPPORTED("""COMPUTED_VALUE"""),43515.6666666666) -> 43515.667 | B34: =IFERROR(__xludf.UNSUPPORTED("""COMPUTED_VALUE"""),3.92) -> 3.92 | C34: =(B34-B33)/B33 -> -0.0025445293
A35: =IFERROR(__xludf.UNSUPPORTED("""COMPUTED_VALUE"""),43516.6666666666) -> 43516.667 | B35: =IFERROR(__xludf.UNSUPPORTED("""COMPUTED_VALUE"""),3.96) -> 3.96 | C35: =(B35-B34)/B34 -> 0.010204082
A36: =IFERROR(__xludf.UNSUPPORTED("""COMPUTED_VALUE"""),43517.6666666666) -> 43517.667 | B36: =IFERROR(__xludf.UNSUPPORTED("""COMPUTED_VALUE"""),3.89) -> 3.89 | C36: =(B36-B35)/B35 -> -0.017676768
A37: =IFERROR(__xludf.UNSUPPORTED("""COMPUTED_VALUE"""),43518.6666666666) -> 43518.667 | B37: =IFERROR(__xludf.UNSUPPORTED("""COMPUTED_VALUE"""),3.98) -> 3.98 | C37: =(B37-B36)/B36 -> 0.023136247
A38: =IFERROR(__xludf.UNSUPPORTED("""COMPUTED_VALUE"""),43521.6666666666) -> 43521.667 | B38: =IFERROR(__xludf.UNSUPPORTED("""COMPUTED_VALUE"""),3.97) -> 3.97 | C38: =(B38-B37)/B37 -> -0.0025125628
A39: =IFERROR(__xludf.UNSUPPORTED("""COMPUTED_VALUE"""),43522.6666666666) -> 43522.667 | B39: =IFERROR(__xludf.UNSUPPORTED("""COMPUTED_VALUE"""),3.93) -> 3.93 | C39: =(B39-B38)/B38 -> -0.010075567
A40: =IFERROR(__xludf.UNSUPPORTED("""COMPUTED_VALUE"""),43523.6666666666) -> 43523.667 | B40: =IFERROR(__xludf.UNSUPPORTED("""COMPUTED_VALUE"""),3.89) -> 3.89 | C40: =(B40-B39)/B39 -> -0.010178117
...

Sheet JPM
A1: =IFERROR(__xludf.UNSUPPORTED(GOOGLEFINANCE("JPM", "price", "01/01/2019", "01/22/2026", "DAILY")),"Date") -> Date | B1: =IFERROR(__xludf.UNSUPPORTED("""COMPUTED_VALUE"""),"Close") -> Close | C1: daily_return | E1: avg_daily_return | F1: volatility | G1: annualized_return | H1: annualized_volatility
A2: =IFERROR(__xludf.UNSUPPORTED("""COMPUTED_VALUE"""),43467.6666666666) -> 43467.667 | B2: =IFERROR(__xludf.UNSUPPORTED("""COMPUTED_VALUE"""),99.31) -> 99.31 | E2: =AVERAGE(C3:C1773) -> 0.00080893763 | F2: =_xlfn.STDEV.S(C3:C1773) -> 0.018879395 | G2: =E2*252 -> 0.20385228 | H2: =F2*SQRT(252) -> 0.2997011
A3: =IFERROR(__xludf.UNSUPPORTED("""COMPUTED_VALUE"""),43468.6666666666) -> 43468.667 | B3: =IFERROR(__xludf.UNSUPPORTED("""COMPUTED_VALUE"""),97.11) -> 97.11 | C3: =(B3-B2)/B2 -> -0.022152855
A4: =IFERROR(__xludf.UNSUPPORTED("""COMPUTED_VALUE"""),43469.6666666666) -> 43469.667 | B4: =IFERROR(__xludf.UNSUPPORTED("""COMPUTED_VALUE"""),100.69) -> 100.69 | C4: =(B4-B3)/B3 -> 0.03686541
A5: =IFERROR(__xludf.UNSUPPORTED("""COMPUTED_VALUE"""),43472.6666666666) -> 43472.667 | B5: =IFERROR(__xludf.UNSUPPORTED("""COMPUTED_VALUE"""),100.76) -> 100.76 | C5: =(B5-B4)/B4 -> 0.0006952031
A6: =IFERROR(__xludf.UNSUPPORTED("""COMPUTED_VALUE"""),43473.6666666666) -> 43473.667 | B6: =IFERROR(__xludf.UNSUPPORTED("""COMPUTED_VALUE"""),100.57) -> 100.57 | C6: =(B6-B5)/B5 -> -0.0018856689
A7: =IFERROR(__xludf.UNSUPPORTED("""COMPUTED_VALUE"""),43474.6666666666) -> 43474.667 | B7: =IFERROR(__xludf.UNSUPPORTED("""COMPUTED_VALUE"""),100.4) -> 100.4 | C7: =(B7-B6)/B6 -> -0.0016903649
A8: =IFERROR(__xludf.UNSUPPORTED("""COMPUTED_VALUE"""),43475.6666666666) -> 43475.667 | B8: =IFERROR(__xludf.UNSUPPORTED("""COMPUTED_VALUE"""),100.39) -> 100.39 | C8: =(B8-B7)/B7 -> -9.9601594e-05
A9: =IFERROR(__xludf.UNSUPPORTED("""COMPUTED_VALUE"""),43476.6666666666) -> 43476.667 | B9: =IFERROR(__xludf.UNSUPPORTED("""COMPUTED_VALUE"""),99.91) -> 99.91 | C9: =(B9-B8)/B8 -> -0.0047813527
A10: =IFERROR(__xludf.UNSUPPORTED("""COMPUTED_VALUE"""),43479.6666666666) -> 43479.667 | B10: =IFERROR(__xludf.UNSUPPORTED("""COMPUTED_VALUE"""),100.94) -> 100.94 | C10: =(B10-B9)/B9 -> 0.010309278
A11: =IFERROR(__xludf.UNSUPPORTED("""COMPUTED_VALUE"""),43480.6666666666) -> 43480.667 | B11: =IFERROR(__xludf.UNSUPPORTED("""COMPUTED_VALUE"""),101.68) -> 101.68 | C11: =(B11-B10)/B10 -> 0.0073310878
A12: =IFERROR(__xludf.UNSUPPORTED("""COMPUTED_VALUE"""),43481.6666666666) -> 43481.667 | B12: =IFERROR(__xludf.UNSUPPORTED("""COMPUTED_VALUE"""),102.5) -> 102.5 | C12: =(B12-B11)/B11 -> 0.0080645161
A13: =IFERROR(__xludf.UNSUPPORTED("""COMPUTED_VALUE"""),43482.6666666666) -> 43482.667 | B13: =IFERROR(__xludf.UNSUPPORTED("""COMPUTED_VALUE"""),102.92) -> 102.92 | C13: =(B13-B12)/B12 -> 0.004097561
A14: =IFERROR(__xludf.UNSUPPORTED("""COMPUTED_VALUE"""),43483.6666666666) -> 43483.667 | B14: =IFERROR(__xludf.UNSUPPORTED("""COMPUTED_VALUE"""),104.59) -> 104.59 | C14: =(B14-B13)/B13 -> 0.016226195
A15: =IFERROR(__xludf.UNSUPPORTED("""COMPUTED_VALUE"""),43487.6666666666) -> 43487.667 | B15: =IFERROR(__xludf.UNSUPPORTED("""COMPUTED_VALUE"""),102.94) -> 102.94 | C15: =(B15-B14)/B14 -> -0.015775887
A16: =IFERROR(__xludf.UNSUPPORTED("""COMPUTED_VALUE"""),43488.6666666666) -> 43488.667 | B16: =IFERROR(__xludf.UNSUPPORTED("""COMPUTED_VALUE"""),102.68) -> 102.68 | C16: =(B16-B15)/B15 -> -0.0025257432
A17: =IFERROR(__xludf.UNSUPPORTED("""COMPUTED_VALUE"""),43489.6666666666) -> 43489.667 | B17: =IFERROR(__xludf.UNSUPPORTED("""COMPUTED_VALUE"""),102.74) -> 102.74 | C17: =(B17-B16)/B16 -> 0.0005843397
A18: =IFERROR(__xludf.UNSUPPORTED("""COMPUTED_VALUE"""),43490.6666666666) -> 43490.667 | B18: =IFERROR(__xludf.UNSUPPORTED("""COMPUTED_VALUE"""),103.39) -> 103.39 | C18: =(B18-B17)/B17 -> 0.0063266498
A19: =IFERROR(__xludf.UNSUPPORTED("""COMPUTED_VALUE"""),43493.6666666666) -> 43493.667 | B19: =IFERROR(__xludf.UNSUPPORTED("""COMPUTED_VALUE"""),103.88) -> 103.88 | C19: =(B19-B18)/B18 -> 0.0047393365
A20: =IFERROR(__xludf.UNSUPPORTED("""COMPUTED_VALUE"""),43494.6666666666) -> 43494.667 | B20: =IFERROR(__xludf.UNSUPPORTED("""COMPUTED_VALUE"""),104.17) -> 104.17 | C20: =(B20-B19)/B19 -> 0.0027916827
A21: =IFERROR(__xludf.UNSUPPORTED("""COMPUTED_VALUE"""),43495.6666666666) -> 43495.667 | B21: =IFERROR(__xludf.UNSUPPORTED("""COMPUTED_VALUE"""),104.41) -> 104.41 | C21: =(B21-B20)/B20 -> 0.0023039263
A22: =IFERROR(__xludf.UNSUPPORTED("""COMPUTED_VALUE"""),43496.6666666666) -> 43496.667 | B22: =IFERROR(__xludf.UNSUPPORTED("""COMPUTED_VALUE"""),103.5) -> 103.5 | C22: =(B22-B21)/B21 -> -0.0087156403
A23: =IFERROR(__xludf.UNSUPPORTED("""COMPUTED_VALUE"""),43497.6666666666) -> 43497.667 | B23: =IFERROR(__xludf.UNSUPPORTED("""COMPUTED_VALUE"""),103.88) -> 103.88 | C23: =(B23-B22)/B22 -> 0.0036714976
A24: =IFERROR(__xludf.UNSUPPORTED("""COMPUTED_VALUE"""),43500.6666666666) -> 43500.667 | B24: =IFERROR(__xludf.UNSUPPORTED("""COMPUTED_VALUE"""),104.25) -> 104.25 | C24: =(B24-B23)/B23 -> 0.0035618021
A25: =IFERROR(__xludf.UNSUPPORTED("""COMPUTED_VALUE"""),43501.6666666666) -> 43501.667 | B25: =IFERROR(__xludf.UNSUPPORTED("""COMPUTED_VALUE"""),103.79) -> 103.79 | C25: =(B25-B24)/B24 -> -0.00441247
A26: =IFERROR(__xludf.UNSUPPORTED("""COMPUTED_VALUE"""),43502.6666666666) -> 43502.667 | B26: =IFERROR(__xludf.UNSUPPORTED("""COMPUTED_VALUE"""),103.74) -> 103.74 | C26: =(B26-B25)/B25 -> -0.00048174198
A27: =IFERROR(__xludf.UNSUPPORTED("""COMPUTED_VALUE"""),43503.6666666666) -> 43503.667 | B27: =IFERROR(__xludf.UNSUPPORTED("""COMPUTED_VALUE"""),102.38) -> 102.38 | C27: =(B27-B26)/B26 -> -0.013109697
A28: =IFERROR(__xludf.UNSUPPORTED("""COMPUTED_VALUE"""),43504.6666666666) -> 43504.667 | B28: =IFERROR(__xludf.UNSUPPORTED("""COMPUTED_VALUE"""),101.36) -> 101.36 | C28: =(B28-B27)/B27 -> -0.0099628834
A29: =IFERROR(__xludf.UNSUPPORTED("""COMPUTED_VALUE"""),43507.6666666666) -> 43507.667 | B29: =IFERROR(__xludf.UNSUPPORTED("""COMPUTED_VALUE"""),100.88) -> 100.88 | C29: =(B29-B28)/B28 -> -0.0047355959
A30: =IFERROR(__xludf.UNSUPPORTED("""COMPUTED_VALUE"""),43508.6666666666) -> 43508.667 | B30: =IFERROR(__xludf.UNSUPPORTED("""COMPUTED_VALUE"""),102.6) -> 102.6 | C30: =(B30-B29)/B29 -> 0.01704996
A31: =IFERROR(__xludf.UNSUPPORTED("""COMPUTED_VALUE"""),43509.6666666666) -> 43509.667 | B31: =IFERROR(__xludf.UNSUPPORTED("""COMPUTED_VALUE"""),103.09) -> 103.09 | C31: =(B31-B30)/B30 -> 0.0047758285
A32: =IFERROR(__xludf.UNSUPPORTED("""COMPUTED_VALUE"""),43510.6666666666) -> 43510.667 | B32: =IFERROR(__xludf.UNSUPPORTED("""COMPUTED_VALUE"""),102.42) -> 102.42 | C32: =(B32-B31)/B31 -> -0.0064991755
A33: =IFERROR(__xludf.UNSUPPORTED("""COMPUTED_VALUE"""),43511.6666666666) -> 43511.667 | B33: =IFERROR(__xludf.UNSUPPORTED("""COMPUTED_VALUE"""),105.55) -> 105.55 | C33: =(B33-B32)/B32 -> 0.030560437
A34: =IFERROR(__xludf.UNSUPPORTED("""COMPUTED_VALUE"""),43515.6666666666) -> 43515.667 | B34: =IFERROR(__xludf.UNSUPPORTED("""COMPUTED_VALUE"""),105.18) -> 105.18 | C34: =(B34-B33)/B33 -> -0.0035054477
A35: =IFERROR(__xludf.UNSUPPORTED("""COMPUTED_VALUE"""),43516.6666666666) -> 43516.667 | B35: =IFERROR(__xludf.UNSUPPORTED("""COMPUTED_VALUE"""),105.69) -> 105.69 | C35: =(B35-B34)/B34 -> 0.0048488306
A36: =IFERROR(__xludf.UNSUPPORTED("""COMPUTED_VALUE"""),43517.6666666666) -> 43517.667 | B36: =IFERROR(__xludf.UNSUPPORTED("""COMPUTED_VALUE"""),105.47) -> 105.47 | C36: =(B36-B35)/B35 -> -0.0020815593
A37: =IFERROR(__xludf.UNSUPPORTED("""COMPUTED_VALUE"""),43518.6666666666) -> 43518.667 | B37: =IFERROR(__xludf.UNSUPPORTED("""COMPUTED_VALUE"""),105) -> 105 | C37: =(B37-B36)/B36 -> -0.0044562435
A38: =IFERROR(__xludf.UNSUPPORTED("""COMPUTED_VALUE"""),43521.6666666666) -> 43521.667 | B38: =IFERROR(__xludf.UNSUPPORTED("""COMPUTED_VALUE"""),106.1) -> 106.1 | C38: =(B38-B37)/B37 -> 0.01047619
A39: =IFERROR(__xludf.UNSUPPORTED("""COMPUTED_VALUE"""),43522.6666666666) -> 43522.667 | B39: =IFERROR(__xludf.UNSUPPORTED("""COMPUTED_VALUE"""),105.29) -> 105.29 | C39: =(B39-B38)/B38 -> -0.0076343073
A40: =IFERROR(__xludf.UNSUPPORTED("""COMPUTED_VALUE"""),43523.6666666666) -> 43523.667 | B40: =IFERROR(__xludf.UNSUPPORTED("""COMPUTED_VALUE"""),105.16) -> 105.16 | C40: =(B40-B39)/B39 -> -0.0012346852
...

Sheet BAC
A1: =IFERROR(__xludf.UNSUPPORTED(GOOGLEFINANCE("BAC", "price", "01/01/2019", "01/22/2026", "DAILY")),"Date") -> Date | B1: =IFERROR(__xludf.UNSUPPORTED("""COMPUTED_VALUE"""),"Close") -> Close | C1: daily_return | E1: avg_daily_return | F1: volatility | G1: annualized_return | H1: annualized_volatility
A2: =IFERROR(__xludf.UNSUPPORTED("""COMPUTED_VALUE"""),43467.6666666666) -> 43467.667 | B2: =IFERROR(__xludf.UNSUPPORTED("""COMPUTED_VALUE"""),24.96) -> 24.96 | E2: =AVERAGE(C3:C1775) -> 0.00063433089 | F2: =_xlfn.STDEV.S(C3:C1775) -> 0.0207822 | G2: =E2*252 -> 0.15985138 | H2: =F2*SQRT(252) -> 0.32990719
A3: =IFERROR(__xludf.UNSUPPORTED("""COMPUTED_VALUE"""),43468.6666666666) -> 43468.667 | B3: =IFERROR(__xludf.UNSUPPORTED("""COMPUTED_VALUE"""),24.56) -> 24.56 | C3: =(B3-B2)/B2 -> -0.016025641
A4: =IFERROR(__xludf.UNSUPPORTED("""COMPUTED_VALUE"""),43469.6666666666) -> 43469.667 | B4: =IFERROR(__xludf.UNSUPPORTED("""COMPUTED_VALUE"""),25.58) -> 25.58 | C4: =(B4-B3)/B3 -> 0.041530945
A5: =IFERROR(__xludf.UNSUPPORTED("""COMPUTED_VALUE"""),43472.6666666666) -> 43472.667 | B5: =IFERROR(__xludf.UNSUPPORTED("""COMPUTED_VALUE"""),25.56) -> 25.56 | C5: =(B5-B4)/B4 -> -0.00078186083
A6: =IFERROR(__xludf.UNSUPPORTED("""COMPUTED_VALUE"""),43473.6666666666) -> 43473.667 | B6: =IFERROR(__xludf.UNSUPPORTED("""COMPUTED_VALUE"""),25.51) -> 25.51 | C6: =(B6-B5)/B5 -> -0.0019561815
A7: =IFERROR(__xludf.UNSUPPORTED("""COMPUTED_VALUE"""),43474.6666666666) -> 43474.667 | B7: =IFERROR(__xludf.UNSUPPORTED("""COMPUTED_VALUE"""),25.76) -> 25.76 | C7: =(B7-B6)/B6 -> 0.0098000784
A8: =IFERROR(__xludf.UNSUPPORTED("""COMPUTED_VALUE"""),43475.6666666666) -> 43475.667 | B8: =IFERROR(__xludf.UNSUPPORTED("""COMPUTED_VALUE"""),25.73) -> 25.73 | C8: =(B8-B7)/B7 -> -0.0011645963
A9: =IFERROR(__xludf.UNSUPPORTED("""COMPUTED_VALUE"""),43476.6666666666) -> 43476.667 | B9: =IFERROR(__xludf.UNSUPPORTED("""COMPUTED_VALUE"""),26.03) -> 26.03 | C9: =(B9-B8)/B8 -> 0.011659541
A10: =IFERROR(__xludf.UNSUPPORTED("""COMPUTED_VALUE"""),43479.6666666666) -> 43479.667 | B10: =IFERROR(__xludf.UNSUPPORTED("""COMPUTED_VALUE"""),26.37) -> 26.37 | C10: =(B10-B9)/B9 -> 0.013061852
A11: =IFERROR(__xludf.UNSUPPORTED("""COMPUTED_VALUE"""),43480.6666666666) -> 43480.667 | B11: =IFERROR(__xludf.UNSUPPORTED("""COMPUTED_VALUE"""),26.55) -> 26.55 | C11: =(B11-B10)/B10 -> 0.0068259386
A12: =IFERROR(__xludf.UNSUPPORTED("""COMPUTED_VALUE"""),43481.6666666666) -> 43481.667 | B12: =IFERROR(__xludf.UNSUPPORTED("""COMPUTED_VALUE"""),28.45) -> 28.45 | C12: =(B12-B11)/B11 -> 0.071563089
A13: =IFERROR(__xludf.UNSUPPORTED("""COMPUTED_VALUE"""),43482.6666666666) -> 43482.667 | B13: =IFERROR(__xludf.UNSUPPORTED("""COMPUTED_VALUE"""),28.99) -> 28.99 | C13: =(B13-B12)/B12 -> 0.018980668
A14: =IFERROR(__xludf.UNSUPPORTED("""COMPUTED_VALUE"""),43483.6666666666) -> 43483.667 | B14: =IFERROR(__xludf.UNSUPPORTED("""COMPUTED_VALUE"""),29.3) -> 29.3 | C14: =(B14-B13)/B13 -> 0.010693343
A15: =IFERROR(__xludf.UNSUPPORTED("""COMPUTED_VALUE"""),43487.6666666666) -> 43487.667 | B15: =IFERROR(__xludf.UNSUPPORTED("""COMPUTED_VALUE"""),29.09) -> 29.09 | C15: =(B15-B14)/B14 -> -0.0071672355
A16: =IFERROR(__xludf.UNSUPPORTED("""COMPUTED_VALUE"""),43488.6666666666) -> 43488.667 | B16: =IFERROR(__xludf.UNSUPPORTED("""COMPUTED_VALUE"""),28.92) -> 28.92 | C16: =(B16-B15)/B15 -> -0.0058439326
A17: =IFERROR(__xludf.UNSUPPORTED("""COMPUTED_VALUE"""),43489.6666666666) -> 43489.667 | B17: =IFERROR(__xludf.UNSUPPORTED("""COMPUTED_VALUE"""),29.08) -> 29.08 | C17: =(B17-B16)/B16 -> 0.0055325035
A18: =IFERROR(__xludf.UNSUPPORTED("""COMPUTED_VALUE"""),43490.6666666666) -> 43490.667 | B18: =IFERROR(__xludf.UNSUPPORTED("""COMPUTED_VALUE"""),29.58) -> 29.58 | C18: =(B18-B17)/B17 -> 0.017193948
A19: =IFERROR(__xludf.UNSUPPORTED("""COMPUTED_VALUE"""),43493.6666666666) -> 43493.667 | B19: =IFERROR(__xludf.UNSUPPORTED("""COMPUTED_VALUE"""),29.63) -> 29.63 | C19: =(B19-B18)/B18 -> 0.0016903313
A20: =IFERROR(__xludf.UNSUPPORTED("""COMPUTED_VALUE"""),43494.6666666666) -> 43494.667 | B20: =IFERROR(__xludf.UNSUPPORTED("""COMPUTED_VALUE"""),29.39) -> 29.39 | C20: =(B20-B19)/B19 -> -0.0080998988
A21: =IFERROR(__xludf.UNSUPPORTED("""COMPUTED_VALUE"""),43495.6666666666) -> 43495.667 | B21: =IFERROR(__xludf.UNSUPPORTED("""COMPUTED_VALUE"""),29.07) -> 29.07 | C21: =(B21-B20)/B20 -> -0.010888057
A22: =IFERROR(__xludf.UNSUPPORTED("""COMPUTED_VALUE"""),43496.6666666666) -> 43496.667 | B22: =IFERROR(__xludf.UNSUPPORTED("""COMPUTED_VALUE"""),28.47) -> 28.47 | C22: =(B22-B21)/B21 -> -0.020639835
A23: =IFERROR(__xludf.UNSUPPORTED("""COMPUTED_VALUE"""),43497.6666666666) -> 43497.667 | B23: =IFERROR(__xludf.UNSUPPORTED("""COMPUTED_VALUE"""),28.38) -> 28.38 | C23: =(B23-B22)/B22 -> -0.0031612223
A24: =IFERROR(__xludf.UNSUPPORTED("""COMPUTED_VALUE"""),43500.6666666666) -> 43500.667 | B24: =IFERROR(__xludf.UNSUPPORTED("""COMPUTED_VALUE"""),28.88) -> 28.88 | C24: =(B24-B23)/B23 -> 0.017618041
A25: =IFERROR(__xludf.UNSUPPORTED("""COMPUTED_VALUE"""),43501.6666666666) -> 43501.667 | B25: =IFERROR(__xludf.UNSUPPORTED("""COMPUTED_VALUE"""),28.78) -> 28.78 | C25: =(B25-B24)/B24 -> -0.0034626039
A26: =IFERROR(__xludf.UNSUPPORTED("""COMPUTED_VALUE"""),43502.6666666666) -> 43502.667 | B26: =IFERROR(__xludf.UNSUPPORTED("""COMPUTED_VALUE"""),28.73) -> 28.73 | C26: =(B26-B25)/B25 -> -0.0017373176
A27: =IFERROR(__xludf.UNSUPPORTED("""COMPUTED_VALUE"""),43503.6666666666) -> 43503.667 | B27: =IFERROR(__xludf.UNSUPPORTED("""COMPUTED_VALUE"""),28.24) -> 28.24 | C27: =(B27-B26)/B26 -> -0.017055343
A28: =IFERROR(__xludf.UNSUPPORTED("""COMPUTED_VALUE"""),43504.6666666666) -> 43504.667 | B28: =IFERROR(__xludf.UNSUPPORTED("""COMPUTED_VALUE"""),28.29) -> 28.29 | C28: =(B28-B27)/B27 -> 0.0017705382
A29: =IFERROR(__xludf.UNSUPPORTED("""COMPUTED_VALUE"""),43507.6666666666) -> 43507.667 | B29: =IFERROR(__xludf.UNSUPPORTED("""COMPUTED_VALUE"""),28.41) -> 28.41 | C29: =(B29-B28)/B28 -> 0.0042417815
A30: =IFERROR(__xludf.UNSUPPORTED("""COMPUTED_VALUE"""),43508.6666666666) -> 43508.667 | B30: =IFERROR(__xludf.UNSUPPORTED("""COMPUTED_VALUE"""),28.69) -> 28.69 | C30: =(B30-B29)/B29 -> 0.0098556846
A31: =IFERROR(__xludf.UNSUPPORTED("""COMPUTED_VALUE"""),43509.6666666666) -> 43509.667 | B31: =IFERROR(__xludf.UNSUPPORTED("""COMPUTED_VALUE"""),28.7) -> 28.7 | C31: =(B31-B30)/B30 -> 0.0003485535
A32: =IFERROR(__xludf.UNSUPPORTED("""COMPUTED_VALUE"""),43510.6666666666) -> 43510.667 | B32: =IFERROR(__xludf.UNSUPPORTED("""COMPUTED_VALUE"""),28.39) -> 28.39 | C32: =(B32-B31)/B31 -> -0.010801394
A33: =IFERROR(__xludf.UNSUPPORTED("""COMPUTED_VALUE"""),43511.6666666666) -> 43511.667 | B33: =IFERROR(__xludf.UNSUPPORTED("""COMPUTED_VALUE"""),29.11) -> 29.11 | C33: =(B33-B32)/B32 -> 0.025361043
A34: =IFERROR(__xludf.UNSUPPORTED("""COMPUTED_VALUE"""),43515.6666666666) -> 43515.667 | B34: =IFERROR(__xludf.UNSUPPORTED("""COMPUTED_VALUE"""),29.13) -> 29.13 | C34: =(B34-B33)/B33 -> 0.00068704912
A35: =IFERROR(__xludf.UNSUPPORTED("""COMPUTED_VALUE"""),43516.6666666666) -> 43516.667 | B35: =IFERROR(__xludf.UNSUPPORTED("""COMPUTED_VALUE"""),29.41) -> 29.41 | C35: =(B35-B34)/B34 -> 0.0096120838
A36: =IFERROR(__xludf.UNSUPPORTED("""COMPUTED_VALUE"""),43517.6666666666) -> 43517.667 | B36: =IFERROR(__xludf.UNSUPPORTED("""COMPUTED_VALUE"""),29.29) -> 29.29 | C36: =(B36-B35)/B35 -> -0.0040802448
A37: =IFERROR(__xludf.UNSUPPORTED("""COMPUTED_VALUE"""),43518.6666666666) -> 43518.667 | B37: =IFERROR(__xludf.UNSUPPORTED("""COMPUTED_VALUE"""),29.08) -> 29.08 | C37: =(B37-B36)/B36 -> -0.0071696825
A38: =IFERROR(__xludf.UNSUPPORTED("""COMPUTED_VALUE"""),43521.6666666666) -> 43521.667 | B38: =IFERROR(__xludf.UNSUPPORTED("""COMPUTED_VALUE"""),29.27) -> 29.27 | C38: =(B38-B37)/B37 -> 0.0065337001
A39: =IFERROR(__xludf.UNSUPPORTED("""COMPUTED_VALUE"""),43522.6666666666) -> 43522.667 | B39: =IFERROR(__xludf.UNSUPPORTED("""COMPUTED_VALUE"""),29.29) -> 29.29 | C39: =(B39-B38)/B38 -> 0.00068329347
A40: =IFERROR(__xludf.UNSUPPORTED("""COMPUTED_VALUE"""),43523.6666666666) -> 43523.667 | B40: =IFERROR(__xludf.UNSUPPORTED("""COMPUTED_VALUE"""),29.53) -> 29.53 | C40: =(B40-B39)/B39 -> 0.0081939228
...

Sheet KO
A1: =IFERROR(__xludf.UNSUPPORTED(GOOGLEFINANCE("KO", "price", "01/01/2019", "01/22/2026", "DAILY")),"Date") -> Date | B1: =IFERROR(__xludf.UNSUPPORTED("""COMPUTED_VALUE"""),"Close") -> Close | C1: daily_return | E1: avg_daily_return | F1: volatility | G1: annualized_return | H1: annualized_volatility
A2: =IFERROR(__xludf.UNSUPPORTED("""COMPUTED_VALUE"""),43467.6666666666) -> 43467.667 | B2: =IFERROR(__xludf.UNSUPPORTED("""COMPUTED_VALUE"""),46.93) -> 46.93 | E2: =AVERAGE(C3:C1772) -> 0.00031991262 | F2: =_xlfn.STDEV.S(C3:C1772) -> 0.012544537 | G2: =E2*252 -> 0.080617981 | H2: =F2*SQRT(252) -> 0.19913835
A3: =IFERROR(__xludf.UNSUPPORTED("""COMPUTED_VALUE"""),43468.6666666666) -> 43468.667 | B3: =IFERROR(__xludf.UNSUPPORTED("""COMPUTED_VALUE"""),46.64) -> 46.64 | C3: =(B3-B2)/B2 -> -0.0061794162
A4: =IFERROR(__xludf.UNSUPPORTED("""COMPUTED_VALUE"""),43469.6666666666) -> 43469.667 | B4: =IFERROR(__xludf.UNSUPPORTED("""COMPUTED_VALUE"""),47.57) -> 47.57 | C4: =(B4-B3)/B3 -> 0.019939966
A5: =IFERROR(__xludf.UNSUPPORTED("""COMPUTED_VALUE"""),43472.6666666666) -> 43472.667 | B5: =IFERROR(__xludf.UNSUPPORTED("""COMPUTED_VALUE"""),46.95) -> 46.95 | C5: =(B5-B4)/B4 -> -0.013033424
A6: =IFERROR(__xludf.UNSUPPORTED("""COMPUTED_VALUE"""),43473.6666666666) -> 43473.667 | B6: =IFERROR(__xludf.UNSUPPORTED("""COMPUTED_VALUE"""),47.48) -> 47.48 | C6: =(B6-B5)/B5 -> 0.011288605
A7: =IFERROR(__xludf.UNSUPPORTED("""COMPUTED_VALUE"""),43474.6666666666) -> 43474.667 | B7: =IFERROR(__xludf.UNSUPPORTED("""COMPUTED_VALUE"""),46.57) -> 46.57 | C7: =(B7-B6)/B6 -> -0.019165965
A8: =IFERROR(__xludf.UNSUPPORTED("""COMPUTED_VALUE"""),43475.6666666666) -> 43475.667 | B8: =IFERROR(__xludf.UNSUPPORTED("""COMPUTED_VALUE"""),47.07) -> 47.07 | C8: =(B8-B7)/B7 -> 0.010736526
A9: =IFERROR(__xludf.UNSUPPORTED("""COMPUTED_VALUE"""),43476.6666666666) -> 43476.667 | B9: =IFERROR(__xludf.UNSUPPORTED("""COMPUTED_VALUE"""),47.34) -> 47.34 | C9: =(B9-B8)/B8 -> 0.0057361377
A10: =IFERROR(__xludf.UNSUPPORTED("""COMPUTED_VALUE"""),43479.6666666666) -> 43479.667 | B10: =IFERROR(__xludf.UNSUPPORTED("""COMPUTED_VALUE"""),47.15) -> 47.15 | C10: =(B10-B9)/B9 -> -0.0040135192
A11: =IFERROR(__xludf.UNSUPPORTED("""COMPUTED_VALUE"""),43480.6666666666) -> 43480.667 | B11: =IFERROR(__xludf.UNSUPPORTED("""COMPUTED_VALUE"""),47.57) -> 47.57 | C11: =(B11-B10)/B10 -> 0.0089077413
A12: =IFERROR(__xludf.UNSUPPORTED("""COMPUTED_VALUE"""),43481.6666666666) -> 43481.667 | B12: =IFERROR(__xludf.UNSUPPORTED("""COMPUTED_VALUE"""),46.92) -> 46.92 | C12: =(B12-B11)/B11 -> -0.013664074
A13: =IFERROR(__xludf.UNSUPPORTED("""COMPUTED_VALUE"""),43482.6666666666) -> 43482.667 | B13: =IFERROR(__xludf.UNSUPPORTED("""COMPUTED_VALUE"""),47.06) -> 47.06 | C13: =(B13-B12)/B12 -> 0.0029838022
A14: =IFERROR(__xludf.UNSUPPORTED("""COMPUTED_VALUE"""),43483.6666666666) -> 43483.667 | B14: =IFERROR(__xludf.UNSUPPORTED("""COMPUTED_VALUE"""),47.61) -> 47.61 | C14: =(B14-B13)/B13 -> 0.011687208
A15: =IFERROR(__xludf.UNSUPPORTED("""COMPUTED_VALUE"""),43487.6666666666) -> 43487.667 | B15: =IFERROR(__xludf.UNSUPPORTED("""COMPUTED_VALUE"""),47.72) -> 47.72 | C15: =(B15-B14)/B14 -> 0.002310439
A16: =IFERROR(__xludf.UNSUPPORTED("""COMPUTED_VALUE"""),43488.6666666666) -> 43488.667 | B16: =IFERROR(__xludf.UNSUPPORTED("""COMPUTED_VALUE"""),48.27) -> 48.27 | C16: =(B16-B15)/B15 -> 0.011525566
A17: =IFERROR(__xludf.UNSUPPORTED("""COMPUTED_VALUE"""),43489.6666666666) -> 43489.667 | B17: =IFERROR(__xludf.UNSUPPORTED("""COMPUTED_VALUE"""),47.69) -> 47.69 | C17: =(B17-B16)/B16 -> -0.012015745
A18: =IFERROR(__xludf.UNSUPPORTED("""COMPUTED_VALUE"""),43490.6666666666) -> 43490.667 | B18: =IFERROR(__xludf.UNSUPPORTED("""COMPUTED_VALUE"""),47.37) -> 47.37 | C18: =(B18-B17)/B17 -> -0.0067100021
A19: =IFERROR(__xludf.UNSUPPORTED("""COMPUTED_VALUE"""),43493.6666666666) -> 43493.667 | B19: =IFERROR(__xludf.UNSUPPORTED("""COMPUTED_VALUE"""),47.17) -> 47.17 | C19: =(B19-B18)/B18 -> -0.0042220815
A20: =IFERROR(__xludf.UNSUPPORTED("""COMPUTED_VALUE"""),43494.6666666666) -> 43494.667 | B20: =IFERROR(__xludf.UNSUPPORTED("""COMPUTED_VALUE"""),47.4) -> 47.4 | C20: =(B20-B19)/B19 -> 0.0048759805
A21: =IFERROR(__xludf.UNSUPPORTED("""COMPUTED_VALUE"""),43495.6666666666) -> 43495.667 | B21: =IFERROR(__xludf.UNSUPPORTED("""COMPUTED_VALUE"""),47.86) -> 47.86 | C21: =(B21-B20)/B20 -> 0.0097046414
A22: =IFERROR(__xludf.UNSUPPORTED("""COMPUTED_VALUE"""),43496.6666666666) -> 43496.667 | B22: =IFERROR(__xludf.UNSUPPORTED("""COMPUTED_VALUE"""),48.13) -> 48.13 | C22: =(B22-B21)/B21 -> 0.0056414542
A23: =IFERROR(__xludf.UNSUPPORTED("""COMPUTED_VALUE"""),43497.6666666666) -> 43497.667 | B23: =IFERROR(__xludf.UNSUPPORTED("""COMPUTED_VALUE"""),48.7) -> 48.7 | C23: =(B23-B22)/B22 -> 0.011842925
A24: =IFERROR(__xludf.UNSUPPORTED("""COMPUTED_VALUE"""),43500.6666666666) -> 43500.667 | B24: =IFERROR(__xludf.UNSUPPORTED("""COMPUTED_VALUE"""),49.25) -> 49.25 | C24: =(B24-B23)/B23 -> 0.011293634
A25: =IFERROR(__xludf.UNSUPPORTED("""COMPUTED_VALUE"""),43501.6666666666) -> 43501.667 | B25: =IFERROR(__xludf.UNSUPPORTED("""COMPUTED_VALUE"""),49.26) -> 49.26 | C25: =(B25-B24)/B24 -> 0.00020304569
A26: =IFERROR(__xludf.UNSUPPORTED("""COMPUTED_VALUE"""),43502.6666666666) -> 43502.667 | B26: =IFERROR(__xludf.UNSUPPORTED("""COMPUTED_VALUE"""),49.26) -> 49.26 | C26: =(B26-B25)/B25 -> 0
A27: =IFERROR(__xludf.UNSUPPORTED("""COMPUTED_VALUE"""),43503.6666666666) -> 43503.667 | B27: =IFERROR(__xludf.UNSUPPORTED("""COMPUTED_VALUE"""),49.42) -> 49.42 | C27: =(B27-B26)/B26 -> 0.0032480715
A28: =IFERROR(__xludf.UNSUPPORTED("""COMPUTED_VALUE"""),43504.6666666666) -> 43504.667 | B28: =IFERROR(__xludf.UNSUPPORTED("""COMPUTED_VALUE"""),49.5) -> 49.5 | C28: =(B28-B27)/B27 -> 0.0016187778
A29: =IFERROR(__xludf.UNSUPPORTED("""COMPUTED_VALUE"""),43507.6666666666) -> 43507.667 | B29: =IFERROR(__xludf.UNSUPPORTED("""COMPUTED_VALUE"""),49.61) -> 49.61 | C29: =(B29-B28)/B28 -> 0.0022222222
A30: =IFERROR(__xludf.UNSUPPORTED("""COMPUTED_VALUE"""),43508.6666666666) -> 43508.667 | B30: =IFERROR(__xludf.UNSUPPORTED("""COMPUTED_VALUE"""),49.66) -> 49.66 | C30: =(B30-B29)/B29 -> 0.0010078613
A31: =IFERROR(__xludf.UNSUPPORTED("""COMPUTED_VALUE"""),43509.6666666666) -> 43509.667 | B31: =IFERROR(__xludf.UNSUPPORTED("""COMPUTED_VALUE"""),49.79) -> 49.79 | C31: =(B31-B30)/B30 -> 0.002617801
A32: =IFERROR(__xludf.UNSUPPORTED("""COMPUTED_VALUE"""),43510.6666666666) -> 43510.667 | B32: =IFERROR(__xludf.UNSUPPORTED("""COMPUTED_VALUE"""),45.59) -> 45.59 | C32: =(B32-B31)/B31 -> -0.084354288
A33: =IFERROR(__xludf.UNSUPPORTED("""COMPUTED_VALUE"""),43511.6666666666) -> 43511.667 | B33: =IFERROR(__xludf.UNSUPPORTED("""COMPUTED_VALUE"""),45.24) -> 45.24 | C33: =(B33-B32)/B32 -> -0.0076771222
A34: =IFERROR(__xludf.UNSUPPORTED("""COMPUTED_VALUE"""),43515.6666666666) -> 43515.667 | B34: =IFERROR(__xludf.UNSUPPORTED("""COMPUTED_VALUE"""),44.83) -> 44.83 | C34: =(B34-B33)/B33 -> -0.0090627763
A35: =IFERROR(__xludf.UNSUPPORTED("""COMPUTED_VALUE"""),43516.6666666666) -> 43516.667 | B35: =IFERROR(__xludf.UNSUPPORTED("""COMPUTED_VALUE"""),45.1) -> 45.1 | C35: =(B35-B34)/B34 -> 0.0060227526
A36: =IFERROR(__xludf.UNSUPPORTED("""COMPUTED_VALUE"""),43517.6666666666) -> 43517.667 | B36: =IFERROR(__xludf.UNSUPPORTED("""COMPUTED_VALUE"""),45.86) -> 45.86 | C36: =(B36-B35)/B35 -> 0.016851441
A37: =IFERROR(__xludf.UNSUPPORTED("""COMPUTED_VALUE"""),43518.6666666666) -> 43518.667 | B37: =IFERROR(__xludf.UNSUPPORTED("""COMPUTED_VALUE"""),45.28) -> 45.28 | C37: =(B37-B36)/B36 -> -0.012647187
A38: =IFERROR(__xludf.UNSUPPORTED("""COMPUTED_VALUE"""),43521.6666666666) -> 43521.667 | B38: =IFERROR(__xludf.UNSUPPORTED("""COMPUTED_VALUE"""),44.94) -> 44.94 | C38: =(B38-B37)/B37 -> -0.0075088339
A39: =IFERROR(__xludf.UNSUPPORTED("""COMPUTED_VALUE"""),43522.6666666666) -> 43522.667 | B39: =IFERROR(__xludf.UNSUPPORTED("""COMPUTED_VALUE"""),44.69) -> 44.69 | C39: =(B39-B38)/B38 -> -0.0055629729
A40: =IFERROR(__xludf.UNSUPPORTED("""COMPUTED_VALUE"""),43523.6666666666) -> 43523.667 | B40: =IFERROR(__xludf.UNSUPPORTED("""COMPUTED_VALUE"""),44.94) -> 44.94 | C40: =(B40-B39)/B39 -> 0.0055940926
...

Sheet SPY
A1: =IFERROR(__xludf.UNSUPPORTED(GOOGLEFINANCE("SPY", "price", "01/01/2019", "01/22/2026", "DAILY")),"Date") -> Date | B1: =IFERROR(__xludf.UNSUPPORTED("""COMPUTED_VALUE"""),"Close") -> Close | C1: daily_return | E1: avg_daily_return | F1: volatility | G1: annualized_return | H1: annualized_volatility
A2: =IFERROR(__xludf.UNSUPPORTED("""COMPUTED_VALUE"""),43467.6666666666) -> 43467.667 | B2: =IFERROR(__xludf.UNSUPPORTED("""COMPUTED_VALUE"""),250.18) -> 250.18 | E2: =AVERAGE(C3:C1775) -> 0.00064941407 | F2: =_xlfn.STDEV.S(C3:C1775) -> 0.012465144 | G2: =E2*252 -> 0.16365235 | H2: =F2*SQRT(252) -> 0.19787803
A3: =IFERROR(__xludf.UNSUPPORTED("""COMPUTED_VALUE"""),43468.6666666666) -> 43468.667 | B3: =IFERROR(__xludf.UNSUPPORTED("""COMPUTED_VALUE"""),244.21) -> 244.21 | C3: =(B3-B2)/B2 -> -0.023862819
A4: =IFERROR(__xludf.UNSUPPORTED("""COMPUTED_VALUE"""),43469.6666666666) -> 43469.667 | B4: =IFERROR(__xludf.UNSUPPORTED("""COMPUTED_VALUE"""),252.39) -> 252.39 | C4: =(B4-B3)/B3 -> 0.033495762
A5: =IFERROR(__xludf.UNSUPPORTED("""COMPUTED_VALUE"""),43472.6666666666) -> 43472.667 | B5: =IFERROR(__xludf.UNSUPPORTED("""COMPUTED_VALUE"""),254.38) -> 254.38 | C5: =(B5-B4)/B4 -> 0.007884623
A6: =IFERROR(__xludf.UNSUPPORTED("""COMPUTED_VALUE"""),43473.6666666666) -> 43473.667 | B6: =IFERROR(__xludf.UNSUPPORTED("""COMPUTED_VALUE"""),256.77) -> 256.77 | C6: =(B6-B5)/B5 -> 0.0093953927
A7: =IFERROR(__xludf.UNSUPPORTED("""COMPUTED_VALUE"""),43474.6666666666) -> 43474.667 | B7: =IFERROR(__xludf.UNSUPPORTED("""COMPUTED_VALUE"""),257.97) -> 257.97 | C7: =(B7-B6)/B6 -> 0.0046734432
A8: =IFERROR(__xludf.UNSUPPORTED("""COMPUTED_VALUE"""),43475.6666666666) -> 43475.667 | B8: =IFERROR(__xludf.UNSUPPORTED("""COMPUTED_VALUE"""),258.88) -> 258.88 | C8: =(B8-B7)/B7 -> 0.003527542
A9: =IFERROR(__xludf.UNSUPPORTED("""COMPUTED_VALUE"""),43476.6666666666) -> 43476.667 | B9: =IFERROR(__xludf.UNSUPPORTED("""COMPUTED_VALUE"""),258.98) -> 258.98 | C9: =(B9-B8)/B8 -> 0.00038627936
A10: =IFERROR(__xludf.UNSUPPORTED("""COMPUTED_VALUE"""),43479.6666666666) -> 43479.667 | B10: =IFERROR(__xludf.UNSUPPORTED("""COMPUTED_VALUE"""),257.4) -> 257.4 | C10: =(B10-B9)/B9 -> -0.0061008572
A11: =IFERROR(__xludf.UNSUPPORTED("""COMPUTED_VALUE"""),43480.6666666666) -> 43480.667 | B11: =IFERROR(__xludf.UNSUPPORTED("""COMPUTED_VALUE"""),260.35) -> 260.35 | C11: =(B11-B10)/B10 -> 0.011460761
A12: =IFERROR(__xludf.UNSUPPORTED("""COMPUTED_VALUE"""),43481.6666666666) -> 43481.667 | B12: =IFERROR(__xludf.UNSUPPORTED("""COMPUTED_VALUE"""),260.98) -> 260.98 | C12: =(B12-B11)/B11 -> 0.0024198195
A13: =IFERROR(__xludf.UNSUPPORTED("""COMPUTED_VALUE"""),43482.6666666666) -> 43482.667 | B13: =IFERROR(__xludf.UNSUPPORTED("""COMPUTED_VALUE"""),262.96) -> 262.96 | C13: =(B13-B12)/B12 -> 0.0075867883
A14: =IFERROR(__xludf.UNSUPPORTED("""COMPUTED_VALUE"""),43483.6666666666) -> 43483.667 | B14: =IFERROR(__xludf.UNSUPPORTED("""COMPUTED_VALUE"""),266.46) -> 266.46 | C14: =(B14-B13)/B13 -> 0.013310009
A15: =IFERROR(__xludf.UNSUPPORTED("""COMPUTED_VALUE"""),43487.6666666666) -> 43487.667 | B15: =IFERROR(__xludf.UNSUPPORTED("""COMPUTED_VALUE"""),262.86) -> 262.86 | C15: =(B15-B14)/B14 -> -0.013510471
A16: =IFERROR(__xludf.UNSUPPORTED("""COMPUTED_VALUE"""),43488.6666666666) -> 43488.667 | B16: =IFERROR(__xludf.UNSUPPORTED("""COMPUTED_VALUE"""),263.41) -> 263.41 | C16: =(B16-B15)/B15 -> 0.0020923686
A17: =IFERROR(__xludf.UNSUPPORTED("""COMPUTED_VALUE"""),43489.6666666666) -> 43489.667 | B17: =IFERROR(__xludf.UNSUPPORTED("""COMPUTED_VALUE"""),263.55) -> 263.55 | C17: =(B17-B16)/B16 -> 0.00053149083
A18: =IFERROR(__xludf.UNSUPPORTED("""COMPUTED_VALUE"""),43490.6666666666) -> 43490.667 | B18: =IFERROR(__xludf.UNSUPPORTED("""COMPUTED_VALUE"""),265.78) -> 265.78 | C18: =(B18-B17)/B17 -> 0.0084613925
A19: =IFERROR(__xludf.UNSUPPORTED("""COMPUTED_VALUE"""),43493.6666666666) -> 43493.667 | B19: =IFERROR(__xludf.UNSUPPORTED("""COMPUTED_VALUE"""),263.76) -> 263.76 | C19: =(B19-B18)/B18 -> -0.0076002709
A20: =IFERROR(__xludf.UNSUPPORTED("""COMPUTED_VALUE"""),43494.6666666666) -> 43494.667 | B20: =IFERROR(__xludf.UNSUPPORTED("""COMPUTED_VALUE"""),263.41) -> 263.41 | C20: =(B20-B19)/B19 -> -0.0013269639
A21: =IFERROR(__xludf.UNSUPPORTED("""COMPUTED_VALUE"""),43495.6666666666) -> 43495.667 | B21: =IFERROR(__xludf.UNSUPPORTED("""COMPUTED_VALUE"""),267.58) -> 267.58 | C21: =(B21-B20)/B20 -> 0.015830834
A22: =IFERROR(__xludf.UNSUPPORTED("""COMPUTED_VALUE"""),43496.6666666666) -> 43496.667 | B22: =IFERROR(__xludf.UNSUPPORTED("""COMPUTED_VALUE"""),269.93) -> 269.93 | C22: =(B22-B21)/B21 -> 0.0087824202
A23: =IFERROR(__xludf.UNSUPPORTED("""COMPUTED_VALUE"""),43497.6666666666) -> 43497.667 | B23: =IFERROR(__xludf.UNSUPPORTED("""COMPUTED_VALUE"""),270.06) -> 270.06 | C23: =(B23-B22)/B22 -> 0.00048160634
A24: =IFERROR(__xludf.UNSUPPORTED("""COMPUTED_VALUE"""),43500.6666666666) -> 43500.667 | B24: =IFERROR(__xludf.UNSUPPORTED("""COMPUTED_VALUE"""),271.96) -> 271.96 | C24: =(B24-B23)/B23 -> 0.0070354736
A25: =IFERROR(__xludf.UNSUPPORTED("""COMPUTED_VALUE"""),43501.6666666666) -> 43501.667 | B25: =IFERROR(__xludf.UNSUPPORTED("""COMPUTED_VALUE"""),273.1) -> 273.1 | C25: =(B25-B24)/B24 -> 0.0041917929
A26: =IFERROR(__xludf.UNSUPPORTED("""COMPUTED_VALUE"""),43502.6666666666) -> 43502.667 | B26: =IFERROR(__xludf.UNSUPPORTED("""COMPUTED_VALUE"""),272.74) -> 272.74 | C26: =(B26-B25)/B25 -> -0.0013181985
A27: =IFERROR(__xludf.UNSUPPORTED("""COMPUTED_VALUE"""),43503.6666666666) -> 43503.667 | B27: =IFERROR(__xludf.UNSUPPORTED("""COMPUTED_VALUE"""),270.14) -> 270.14 | C27: =(B27-B26)/B26 -> -0.0095328885
A28: =IFERROR(__xludf.UNSUPPORTED("""COMPUTED_VALUE"""),43504.6666666666) -> 43504.667 | B28: =IFERROR(__xludf.UNSUPPORTED("""COMPUTED_VALUE"""),270.47) -> 270.47 | C28: =(B28-B27)/B27 -> 0.0012215888
A29: =IFERROR(__xludf.UNSUPPORTED("""COMPUTED_VALUE"""),43507.6666666666) -> 43507.667 | B29: =IFERROR(__xludf.UNSUPPORTED("""COMPUTED_VALUE"""),270.62) -> 270.62 | C29: =(B29-B28)/B28 -> 0.00055459016
A30: =IFERROR(__xludf.UNSUPPORTED("""COMPUTED_VALUE"""),43508.6666666666) -> 43508.667 | B30: =IFERROR(__xludf.UNSUPPORTED("""COMPUTED_VALUE"""),274.1) -> 274.1 | C30: =(B30-B29)/B29 -> 0.01285936
A31: =IFERROR(__xludf.UNSUPPORTED("""COMPUTED_VALUE"""),43509.6666666666) -> 43509.667 | B31: =IFERROR(__xludf.UNSUPPORTED("""COMPUTED_VALUE"""),274.99) -> 274.99 | C31: =(B31-B30)/B30 -> 0.0032469901
A32: =IFERROR(__xludf.UNSUPPORTED("""COMPUTED_VALUE"""),43510.6666666666) -> 43510.667 | B32: =IFERROR(__xludf.UNSUPPORTED("""COMPUTED_VALUE"""),274.38) -> 274.38 | C32: =(B32-B31)/B31 -> -0.0022182625
A33: =IFERROR(__xludf.UNSUPPORTED("""COMPUTED_VALUE"""),43511.6666666666) -> 43511.667 | B33: =IFERROR(__xludf.UNSUPPORTED("""COMPUTED_VALUE"""),277.37) -> 277.37 | C33: =(B33-B32)/B32 -> 0.010897296
A34: =IFERROR(__xludf.UNSUPPORTED("""COMPUTED_VALUE"""),43515.6666666666) -> 43515.667 | B34: =IFERROR(__xludf.UNSUPPORTED("""COMPUTED_VALUE"""),277.85) -> 277.85 | C34: =(B34-B33)/B33 -> 0.0017305404
A35: =IFERROR(__xludf.UNSUPPORTED("""COMPUTED_VALUE"""),43516.6666666666) -> 43516.667 | B35: =IFERROR(__xludf.UNSUPPORTED("""COMPUTED_VALUE"""),278.41) -> 278.41 | C35: =(B35-B34)/B34 -> 0.002015476
A36: =IFERROR(__xludf.UNSUPPORTED("""COMPUTED_VALUE"""),43517.6666666666) -> 43517.667 | B36: =IFERROR(__xludf.UNSUPPORTED("""COMPUTED_VALUE"""),277.42) -> 277.42 | C36: =(B36-B35)/B35 -> -0.0035559068
A37: =IFERROR(__xludf.UNSUPPORTED("""COMPUTED_VALUE"""),43518.6666666666) -> 43518.667 | B37: =IFERROR(__xludf.UNSUPPORTED("""COMPUTED_VALUE"""),279.14) -> 279.14 | C37: =(B37-B36)/B36 -> 0.0061999856
A38: =IFERROR(__xludf.UNSUPPORTED("""COMPUTED_VALUE"""),43521.6666666666) -> 43521.667 | B38: =IFERROR(__xludf.UNSUPPORTED("""COMPUTED_VALUE"""),279.52) -> 279.52 | C38: =(B38-B37)/B37 -> 0.0013613241
A39: =IFERROR(__xludf.UNSUPPORTED("""COMPUTED_VALUE"""),43522.6666666666) -> 43522.667 | B39: =IFERROR(__xludf.UNSUPPORTED("""COMPUTED_VALUE"""),279.32) -> 279.32 | C39: =(B39-B38)/B38 -> -0.00071551231
A40: =IFERROR(__xludf.UNSUPPORTED("""COMPUTED_VALUE"""),43523.6666666666) -> 43523.667 | B40: =IFERROR(__xludf.UNSUPPORTED("""COMPUTED_VALUE"""),279.2) -> 279.2 | C40: =(B40-B39)/B39 -> -0.00042961478
...
